:meth:`asyncio.futures.Future.set_exception()` now transforms ``StopIteration``
into ``RuntimeError`` instead of hanging or other misbehavior. Patch
contributed by Jamie Phan.
