Fixed :exc:`AssertionError` when using :func:`!asyncio.staggered.staggered_task` with :attr:`asyncio.eager_task_factory`.
